<?xml version="1.0"?>
<robot name="yaoi" xmlns:xacro="http:/www.ros.org/wiki/xacro">

<xacro:property name="body_x" value="1"/>
<xacro:property name="body_y" value="0.6"/>
<xacro:property name="body_z" value="0.3"/>

<xacro:property name="wheel_radius" value="0.15"/>
<xacro:property name="wheel_length" value="0.1"/>
<xacro:property name="wheel_z" value="-0.1"/>

<xacro:property name="body_density" value="2710.0"/>
<xacro:property name="wheel_density" value="2710.0"/>

<xacro:property name="pi" value="3.14158265"/>

<xacro:property name="body_mass" value="${body_density*body_x*body_y*body_z}"/>
<xacro:property name="wheel_mass" value="${wheel_density*wheel_radius*wheel_radius*wheel_length*pi}"/>

<xacro:property name="Iz_wheel" value="${0.5*wheel_mass*wheel_radius}"/>
<xacro:property name="Ixy_wheel" value="${(1.0/12.0)*wheel_mass*(3.0*wheel_radius*wheel_radius+wheel_length*wheel_length)}"/>

<xacro:macro name="inertia_wheel">
	<inertial>
	<origin rpy="0 0 0" xyz="0 0 0"/>
	<mass value="${wheel_mass}"/>
	<inertia ixx="${Ixy_wheel}" ixy="0" ixz="0" iyy="${Ixy_wheel}" iyz="0" izz="${Iz_wheel}"/>
	</inertial>
</xacro:macro>

<xacro:include filename="$(find robot_model_pkg)/urdf/robot.gazebo" />
	
<link name="dummy">
</link>
<joint name="dummy_joint" type="fixed">
	<parent link="dummy"/>
	<child link="body_link"/>
</joint>
	
	
	
	
<link name="body_link">
	<visual>
		<origin rpy="0 0 0" xzy="0 0 0"/>
		<geometry>
			<box size="${body_x}  ${body_y} ${body_z}" />
		</geometry>
		
		<material name="red">
			<color rgba="1 0 0 1"/>
		</material>
	</visual>
	
	
	<collision>
		<origin rpy="0 0 0" xzy="0 0 0"/>
		<geometry>
			<box size="${body_x} ${body_y} ${body_z}" />
		</geometry>
	</collision>
	
	
	<inertial>
		<origin rpy="0 0 0" xzy="0 0 0"/>
		<mass value="${body_mass}"/>
	<inertia
	ixx="${(1/12)*body_mass*(body_y*body_y+body_z*body_z)}" ixy="0" ixz="0"
	iyy="${(1/12)*body_mass*(body_x*body_x+body_z*body_z)}" iyz="0"
	izz="${(1/12)*body_mass*(body_x*body_x+body_y*body_y)}"/>
	</inertial>
</link>




<joint name="wheel1_joint" type="continuous">
	<parent link="body_link"/>
	<child link="wheel1_link"/>
	<origin xyz="${-body_x/2+1.2*wheel_radius} ${-body_y/2-wheel_length/2} ${wheel_z}" 
	rpy="0 0 0" />
	<axis xyz="0 1 0"/>
	<limit effort="1000" velocity="1000"/>
	<dynamics damping="1.0" friction="1.0"/>
</joint>


<link name="wheel1_link">
	<visual>
		<origin rpy="1.570795 0 0" xyz="0 0 0"/>
		<geometry>
			<cylinder length="${wheel_length}" radius="${wheel_radius}"/>
		</geometry>
		
		<material name="yellow">
			<color rgba="1 1 0 1"/>
		</material>
	</visual>
	
	<collision>
		<origin rpy="1.570795 0 0" xyz="0 0 0"/>
		<geometry>
			<cylinder length="${wheel_length}" radius="${wheel_radius}"/>
		</geometry>
	</collision>
	<xacro:inertia_wheel/>
</link>

<joint name="wheel2_joint" type="continuous">
	<parent link="body_link"/>
	<child link="wheel2_link"/>
	<origin xyz="${-body_x/2+1.2*wheel_radius} ${body_y/2+wheel_length/2} ${wheel_z}" 
	rpy="0 0 0" />
	<axis xyz="0 1 0"/>
	<limit effort="1000" velocity="1000"/>
	<dynamics damping="1.0" friction="1.0"/>
</joint>


<link name="wheel2_link">
	<visual>
		<origin rpy="1.570795 0 0" xyz="0 0 0"/>
		<geometry>
			<cylinder length="${wheel_length}" radius="${wheel_radius}"/>
		</geometry>
		
		<material name="yellow">
			<color rgba="1 1 0 1"/>
		</material>
	</visual>
	
	<collision>
		<origin rpy="1.570795 0 0" xyz="0 0 0"/>
		<geometry>
			<cylinder length="${wheel_length}" radius="${wheel_radius}"/>
		</geometry>
	</collision>
	<xacro:inertia_wheel />
</link>

<joint name="wheel3_joint" type="continuous">
	<parent link="body_link"/>
	<child link="wheel3_link"/>
	<origin xyz="${body_x/2-1.2*wheel_radius} ${-body_y/2-wheel_length/2} ${wheel_z}" 
	rpy="0 0 0" />
	<axis xyz="0 1 0"/>
	<limit effort="1000" velocity="1000"/>
	<dynamics damping="1.0" friction="1.0"/>
</joint>


<link name="wheel3_link">
	<visual>
		<origin rpy="1.570795 0 0" xyz="0 0 0"/>
		<geometry>
			<cylinder length="${wheel_length}" radius="${wheel_radius}"/>
		</geometry>
		
		<material name="yellow">
			<color rgba="1 1 0 1"/>
		</material>
	</visual>
	
	<collision>
		<origin rpy="1.570795 0 0" xyz="0 0 0"/>
		<geometry>
			<cylinder length="${wheel_length}" radius="${wheel_radius}"/>
		</geometry>
	</collision>
	<xacro:inertia_wheel />
</link>

<joint name="wheel4_joint" type="continuous">
	<parent link="body_link"/>
	<child link="wheel4_link"/>
	<origin xyz="${body_x/2-1.2*wheel_radius} ${body_y/2+wheel_length/2} ${wheel_z}" 
	rpy="0 0 0" />
	<axis xyz="0 1 0"/>
	<limit effort="1000" velocity="1000"/>
	<dynamics damping="1.0" friction="1.0"/>
</joint>


<link name="wheel4_link">
	<visual>
		<origin rpy="1.570795 0 0" xyz="0 0 0"/>
		<geometry>
			<cylinder length="${wheel_length}" radius="${wheel_radius}"/>
		</geometry>
		
		<material name="yellow">
			<color rgba="1 1 0 1"/>
		</material>
	</visual>
	
	<collision>
		<origin rpy="1.570795 0 0" xyz="0 0 0"/>
		<geometry>
			<cylinder length="${wheel_length}" radius="${wheel_radius}"/>
		</geometry>
	</collision>
	<xacro:inertia_wheel />
</link>


</robot>
